<?xml version="1.0" ?>
<!-- ======================================================================= -->
<!-- | This document was autogenerated by xacro from lbr_iiwa.urdf.xacro   | -->
<!-- | Original xacro: https://github.com/rtkg/lbr_iiwa/archive/master.zip | -->
<!-- | EDITING THIS FILE BY HAND IS NOT RECOMMENDED                        | -->
<!-- | Changes (kohlhoff):                                                 | -->
<!-- |   * Removed gazebo tags.                                            | -->
<!-- |   * Removed unused materials.                                       | -->
<!-- |   * Made mesh paths relative.                                       | -->
<!-- |   * Removed material fields from collision segments.                | -->
<!-- |   * Removed the self_collision_checking segment.                    | -->
<!-- |   * Removed transmission segments, since they didn't match the      | -->
<!-- |     convention, will have to added back later.                      | -->
<!-- ======================================================================= -->
<!--LICENSE:                                                                 -->
<!--Copyright (c) 2015, Robert Krug & Todor Stoyanov, AASS Research Center,  -->
<!--Orebro University, Sweden                                                -->
<!--All rights reserved.                                                     -->
<!--                                                                         -->
<!--Redistribution and use in source and binary forms, with or without       -->
<!--modification, are permitted provided that the following conditions are   -->
<!--met:                                                                     -->
<!--                                                                         -->
<!--1. Redistributions of source code must retain the above copyright notice,-->
<!--   this list of conditions and the following disclaimer.                 -->
<!--                                                                         -->
<!--2. Redistributions in binary form must reproduce the above copyright     -->
<!--   notice, this list of conditions and the following disclaimer in the   -->
<!--   documentation and/or other materials provided with the distribution.  -->
<!--                                                                         -->
<!--THIS SOFTWARE IS PROVIDED BY THE COPYRIGHT HOLDERS AND CONTRIBUTORS "AS  -->
<!--IS" AND ANY EXPRESS OR IMPLIED WARRANTIES, INCLUDING, BUT NOT LIMITED TO,-->
<!--THE IMPLIED WARRANTIES OF MERCHANTABILITY AND FITNESS FOR A PARTICULAR   -->
<!--PURPOSE ARE DISCLAIMED. IN NO EVENT SHALL THE COPYRIGHT HOLDER OR        -->
<!--CONTRIBUTORS BE LIABLE FOR ANY DIRECT, INDIRECT, INCIDENTAL, SPECIAL,    -->
<!--EXEMPLARY, OR CONSEQUENTIAL DAMAGES (INCLUDING, BUT NOT LIMITED TO,      -->
<!--PROCUREMENT OF SUBSTITUTE GOODS OR SERVICES; LOSS OF USE, DATA, OR       -->
<!--PROFITS; OR BUSINESS INTERRUPTION) HOWEVER CAUSED AND ON ANY THEORY OF   -->
<!--LIABILITY, WHETHER IN CONTRACT, STRICT LIABILITY, OR TORT (INCLUDING     -->
<!--NEGLIGENCE OR OTHERWISE) ARISING IN ANY WAY OUT OF THE USE OF THIS       -->
<!--SOFTWARE, EVEN IF ADVISED OF THE POSSIBILITY OF SUCH DAMAGE.             -->
<robot name="lbr_iiwa" xmlns:xacro="http://www.ros.org/wiki/xacro">
  <!-- Import Rviz colors -->
  <material name="Grey">
    <color rgba="0.2 0.2 0.2 1.0"/>
  </material>
  <material name="Orange">
    <color rgba="1.0 0.423529411765 0.0392156862745 1.0"/>
  </material>
  <material name="Blue">
    <color rgba="0.5 .7 1.0 1.0"/>
  </material>
  <!--Import the lbr iiwa macro -->
  <!--Import Transmissions -->
  <!--Include Utilities -->
  <!--The following macros are adapted from the LWR 4 definitions of the RCPRG - https://github.com/RCPRG-ros-pkg/lwr_robot -->
  <!--Little helper macros to define the inertia matrix needed for links.-->
  <!--Cuboid-->
  <!--Cylinder: length is along the y-axis! -->
  <!--lbr-->
  <link name="lbr_iiwa_link_0">
    <inertial>
      <origin rpy="0 0 0" xyz="-0.1 0 0.07"/>
      <!--Increase mass from 5 Kg original to provide a stable base to carry the
          arm.-->
      <mass value="0.01"/>
      <inertia ixx="0.05" ixy="0" ixz="0" iyy="0.06" iyz="0" izz="0.03"/>
    </inertial>
    <visual>
      <origin rpy="0 0 0" xyz="0 0 0"/>
      <geometry>
        <mesh filename="meshes/link_0.obj"/>
      </geometry>
      <material name="Grey"/>
    </visual>
    <collision>
      <origin rpy="0 0 0" xyz="0 0 0"/>
      <geometry>
        <mesh filename="meshes/link_0.stl"/>
      </geometry>
    </collision>
  </link>
  <!-- joint between link_0 and link_1 -->
  <joint name="lbr_iiwa_joint_1" type="revolute">
    <parent link="lbr_iiwa_link_0"/>
    <child link="lbr_iiwa_link_1"/>
    <origin rpy="0 0 0" xyz="0 0 0.1575"/>
    <axis xyz="0 0 1"/>
    <limit effort="300" lower="-2.96705972839" upper="2.96705972839" velocity="10"/>
    <dynamics damping="0.5"/>
  </joint>
  <link name="lbr_iiwa_link_1">
    <inertial>
      <origin rpy="0 0 0" xyz="0 -0.03 0.12"/>
      <mass value="4"/>
      <inertia ixx="0.1" ixy="0" ixz="0" iyy="0.09" iyz="0" izz="0.02"/>
    </inertial>
    <visual>
      <origin rpy="0 0 0" xyz="0 0 0"/>
      <geometry>
        <mesh filename="meshes/link_1.stl"/>
      </geometry>
      <material name="Blue"/>
    </visual>
    <collision>
      <origin rpy="0 0 0" xyz="0 0 0"/>
      <geometry>
        <mesh filename="meshes/link_1.stl"/>
      </geometry>
    </collision>
  </link>
  <!-- joint between link_1 and link_2 -->
  <joint name="lbr_iiwa_joint_2" type="revolute">
    <parent link="lbr_iiwa_link_1"/>
    <child link="lbr_iiwa_link_2"/>
    <origin rpy="1.57079632679   0 3.14159265359" xyz="0 0 0.2025"/>
    <axis xyz="0 0 1"/>
    <limit effort="300" lower="-2.09439510239" upper="2.09439510239" velocity="10"/>
    <dynamics damping="0.5"/>
  </joint>
  <link name="lbr_iiwa_link_2">
    <inertial>
      <origin rpy="0 0 0" xyz="0.0003 0.059 0.042"/>
      <mass value="4"/>
      <inertia ixx="0.05" ixy="0" ixz="0" iyy="0.018" iyz="0" izz="0.044"/>
    </inertial>
    <visual>
      <origin rpy="0 0 0" xyz="0 0 0"/>
      <geometry>
        <mesh filename="meshes/link_2.stl"/>
      </geometry>
      <material name="Blue"/>
    </visual>
    <collision>
      <origin rpy="0 0 0" xyz="0 0 0"/>
      <geometry>
        <mesh filename="meshes/link_2.stl"/>
      </geometry>
    </collision>
  </link>

  <!-- joint between link_2 and link_3 -->
  <joint name="lbr_iiwa_joint_3" type="revolute">
    <parent link="lbr_iiwa_link_2"/>
    <child link="lbr_iiwa_link_3"/>
    <origin rpy="1.57079632679 0 3.14159265359" xyz="0 0.2045 0"/>
    <axis xyz="0 0 1"/>
    <limit effort="300" lower="-2.96705972839" upper="2.96705972839" velocity="10"/>
    <dynamics damping="0.5"/>
  </joint>
  <link name="lbr_iiwa_link_3">
    <inertial>
      <origin rpy="0 0 0" xyz="0 0.03 0.13"/>
      <mass value="3"/>
      <inertia ixx="0.08" ixy="0" ixz="0" iyy="0.075" iyz="0" izz="0.01"/>
    </inertial>
    <visual>
      <origin rpy="0 0 0" xyz="0 0 0"/>
      <geometry>
        <mesh filename="meshes/link_3.stl"/>
      </geometry>
      <material name="Orange"/>
    </visual>
    <collision>
      <origin rpy="0 0 0" xyz="0 0 0"/>
      <geometry>
        <mesh filename="meshes/link_3.stl"/>
      </geometry>
    </collision>
  </link>
  <!-- joint between link_3 and link_4 -->
  <joint name="lbr_iiwa_joint_4" type="revolute">
    <parent link="lbr_iiwa_link_3"/>
    <child link="lbr_iiwa_link_4"/>
    <origin rpy="1.57079632679 0 0" xyz="0 0 0.2155"/>
    <axis xyz="0 0 1"/>
    <limit effort="300" lower="-2.09439510239" upper="2.09439510239" velocity="10"/>
    <dynamics damping="0.5"/>
  </joint>
  <link name="lbr_iiwa_link_4">
    <inertial>
      <origin rpy="0 0 0" xyz="0 0.067 0.034"/>
      <mass value="2.7"/>
      <inertia ixx="0.03" ixy="0" ixz="0" iyy="0.01" iyz="0" izz="0.029"/>
    </inertial>
    <visual>
      <origin rpy="0 0 0" xyz="0 0 0"/>
      <geometry>
        <mesh filename="meshes/link_4.stl"/>
      </geometry>
      <material name="Blue"/>
    </visual>
    <collision>
      <origin rpy="0 0 0" xyz="0 0 0"/>
      <geometry>
        <mesh filename="meshes/link_4.stl"/>
      </geometry>
    </collision>
  </link>
  <!-- joint between link_4 and link_5 -->
  <joint name="lbr_iiwa_joint_5" type="revolute">
    <parent link="lbr_iiwa_link_4"/>
    <child link="lbr_iiwa_link_5"/>
    <origin rpy="-1.57079632679 3.14159265359 0" xyz="0 0.1845 0"/>
    <axis xyz="0 0 1"/>
    <limit effort="300" lower="-2.96705972839" upper="2.96705972839" velocity="10"/>
    <dynamics damping="0.5"/>
  </joint>
  <link name="lbr_iiwa_link_5">
    <inertial>
      <origin rpy="0 0 0" xyz="0.0001 0.021 0.076"/>
      <mass value="1.7"/>
      <inertia ixx="0.02" ixy="0" ixz="0" iyy="0.018" iyz="0" izz="0.005"/>
    </inertial>
    <visual>
      <origin rpy="0 0 0" xyz="0 0 0"/>
      <geometry>
        <mesh filename="meshes/link_5.stl"/>
      </geometry>
      <material name="Blue"/>
    </visual>
    <collision>
      <origin rpy="0 0 0" xyz="0 0 0"/>
      <geometry>
        <mesh filename="meshes/link_5.stl"/>
      </geometry>
    </collision>
  </link>
  <!-- joint between link_5 and link_6 -->
  <joint name="lbr_iiwa_joint_6" type="revolute">
    <parent link="lbr_iiwa_link_5"/>
    <child link="lbr_iiwa_link_6"/>
    <origin rpy="1.57079632679 0 0" xyz="0 0 0.2155"/>
    <axis xyz="0 0 1"/>
    <limit effort="300" lower="-2.09439510239" upper="2.09439510239" velocity="10"/>
    <dynamics damping="0.5"/>
  </joint>
  <link name="lbr_iiwa_link_6">
    <inertial>
      <origin rpy="0 0 0" xyz="0 0.0006 0.0004"/>
      <mass value="1.8"/>
      <inertia ixx="0.005" ixy="0" ixz="0" iyy="0.0036" iyz="0" izz="0.0047"/>
    </inertial>
    <visual>
      <origin rpy="0 0 0" xyz="0 0 0"/>
      <geometry>
        <mesh filename="meshes/link_6.stl"/>
      </geometry>
      <material name="Orange"/>
    </visual>
    <collision>
      <origin rpy="0 0 0" xyz="0 0 0"/>
      <geometry>
        <mesh filename="meshes/link_6.stl"/>
      </geometry>
    </collision>
  </link>
  <!-- joint between link_6 and link_7 -->
  <joint name="lbr_iiwa_joint_7" type="revolute">
    <parent link="lbr_iiwa_link_6"/>
    <child link="lbr_iiwa_link_7"/>
    <origin rpy="-1.57079632679 3.14159265359 0" xyz="0 0.081 0"/>
    <axis xyz="0 0 1"/>
    <limit effort="300" lower="-3.05432619099" upper="3.05432619099" velocity="10"/>
    <dynamics damping="0.5"/>
  </joint>
  <link name="lbr_iiwa_link_7">
    <inertial>
      <origin rpy="0 0 0" xyz="0 0 0.02"/>
      <mass value="0.3"/>
      <inertia ixx="0.001" ixy="0" ixz="0" iyy="0.001" iyz="0" izz="0.001"/>
    </inertial>
    <visual>
      <origin rpy="0 0 0" xyz="0 0 0"/>
      <geometry>
        <mesh filename="meshes/link_7.stl"/>
      </geometry>
      <material name="Grey"/>
    </visual>
    <collision>
      <origin rpy="0 0 0" xyz="0 0 0"/>
      <geometry>
        <mesh filename="meshes/link_7.stl"/>
      </geometry>
    </collision>
  </link>

  <joint name="victor_left_arm_joint_flange" type="fixed">
    <parent link="lbr_iiwa_link_7"/>
    <child link="victor_left_arm_flange"/>
    <origin rpy="0 0 0" xyz="0 0 0.045"/>
  </joint>
  <link name="victor_left_arm_flange">
    <inertial>
      <origin rpy="0 0 0" xyz="0 0 0"/>
      <mass value="1"/>
      <inertia ixx="1" ixy="0" ixz="0" iyy="1" iyz="0" izz="1"/>
    </inertial>
        </link>
  <!-- Our usage above has been tweaked to match Kuka's internal usage, so identity transform -->
  <joint name="victor_left_arm_flange_kuka_joint" type="fixed">
    <parent link="victor_left_arm_flange"/>
    <child link="victor_left_arm_flange_kuka"/>
    <origin rpy="0 0 0" xyz="0 0 0"/>
  </joint>
  <link name="victor_left_arm_flange_kuka">
    <inertial>
      <origin rpy="0 0 0" xyz="0 0 0"/>
      <mass value="1"/>
      <inertia ixx="1" ixy="0" ixz="0" iyy="1" iyz="0" izz="1"/>
    </inertial>
        </link>

  <joint name="victor_left_arm_flange_victor_left_joint" type="fixed">
    <origin rpy="0 0 0" xyz="0 0 -0.01"/>
    <parent link="victor_left_arm_flange"/>
    <child link="victor_left_gripper_mounting_bracket"/>
  </joint>
  <link name="victor_left_gripper_mounting_bracket">
    <visual>
      <origin rpy="0 0 0" xyz="0 0 0"/>
      <geometry>
        <mesh filename="meshes/robotiq_3finger/kuka_to_palm_connectors_visual.stl"/>
      </geometry>
      <material name="LightGrey"/>
    </visual>
    <collision>
      <origin rpy="0 0 0" xyz="0 0 0"/>
      <geometry>
        <mesh filename="meshes/robotiq_3finger/kuka_to_palm_connectors_collision.stl"/>
      </geometry>
      <material name="LightGrey"/>
    </collision>
    <inertial>
      <origin rpy="0 0 0" xyz="0 0 0"/>
      <mass value="1"/>
      <inertia ixx="1" ixy="0" ixz="0" iyy="1" iyz="0" izz="1"/>
    </inertial>
  </link>


  <joint name="l_robotiq_hand_joint" type="fixed">
    <origin rpy="1.5707963267948966 0 3.14159265" xyz="0 0 0.07"/>
    <parent link="victor_left_gripper_mounting_bracket"/>
    <child link="l_palm"/>
  </joint>
  <link name="l_finger_1_link_0">
    <visual>
      <origin rpy="0 0 0" xyz="0.020 0 0"/>
      <geometry>
        <mesh filename="meshes/robotiq/visual/link_0.obj"/>
      </geometry>
      <material name="grey">
        <color rgba="0.3 0.3 0.3 1"/>
      </material>
    </visual>
    <inertial>
      <origin rpy="0 0 0" xyz="0 0 0"/>
      <mass value="0.02133"/>
      <inertia ixx="4.598e-06" ixy="2.211e-07" ixz="0.0" iyy="4.441e-06" iyz="0.0" izz="5.906e-06"/>
    </inertial>
  </link>
  <link name="l_finger_1_link_1">
    <visual>
      <origin rpy="0 0 -0.52" xyz="0.050 -.028 0"/>
      <geometry>
        <mesh filename="meshes/robotiq/visual/link_1.obj"/>
      </geometry>
      <material name="grey"/>
    </visual>
    <collision>
      <origin rpy="0 0 -0.61" xyz="0.028 -0.016 0.0"/>
      <geometry>
        <box size="0.048 0.018 0.0308"/>
      </geometry>
      <material name="red">
        <color rgba="1 0 0 1"/>
      </material>
      <surface>
        <friction>
          <ode>
            <mu>1.5</mu>
            <mu2>1.0</mu2>
          </ode>
        </friction>
      </surface>
    </collision>
    <inertial>
      <origin rpy="0 0 0" xyz="0 0 0"/>
      <mass value="0.10489"/>
      <inertia ixx="1.655e-05" ixy="-5.844e-07" ixz="0.0" iyy="7.334e-05" iyz="0.0" izz="8.054e-05"/>
    </inertial>
  </link>
  <link name="l_finger_1_link_2">
    <!--
				NOTE: This link has an offset in the z-direction based on the models that were
				used to generate grap-it poses.  With the offset below the model appears visually
				correct, but it is suspect.
				-->
    <visual>
      <origin rpy="0 0 0" xyz="0.039 0 0.0075"/>
      <geometry>
        <mesh filename="meshes/robotiq/visual/link_2.obj"/>
      </geometry>
      <material name="grey"/>
    </visual>
    <collision>
      <origin rpy="0 0 0.0" xyz="0.023 0.002 0.0"/>
      <geometry>
        <box size="0.0285 0.01 0.0308"/>
      </geometry>
      <material name="red">
        <color rgba="1 0 0 1"/>
      </material>
      <surface>
        <friction>
          <ode>
            <mu>1.5</mu>
            <mu2>1.0</mu2>
          </ode>
        </friction>
      </surface>
    </collision>
    <inertial>
      <origin rpy="0 0 0" xyz="0 0 0"/>
      <mass value="0.0601"/>
      <inertia ixx="7.304e-06" ixy="-2.645e-06" ixz="3.537e-07" iyy="1.918e-05" iyz="6.920e-07" izz="2.214e-05"/>
    </inertial>
  </link>
  <link name="l_finger_1_link_3">
    <visual>
      <origin rpy="0 0 0.52" xyz="0 0 0"/>
      <geometry>
        <mesh filename="meshes/robotiq/visual/link_3.obj"/>
      </geometry>
      <material name="grey"/>
    </visual>
    <collision>
      <origin rpy="0 0 0.58" xyz="0.015 0.0135 0.0"/>
      <geometry>
        <box size="0.03 0.007 0.0308"/>
      </geometry>
      <material name="red">
        <color rgba="1 0 0 1"/>
      </material>
      <surface>
        <friction>
          <ode>
            <mu>1.5</mu>
            <mu2>1.0</mu2>
          </ode>
        </friction>
      </surface>
    </collision>
    <inertial>
      <origin rpy="0 0 0" xyz="0 0 0"/>
      <mass value="0.024"/>
      <inertia ixx="2.021e-06" ixy="-7.733e-07" ixz="-1.031e-08" iyy="4.908e-06" iyz="0.0" izz="4.578e-06"/>
    </inertial>
  </link>
  <joint name="l_finger_1_joint_1" type="revolute">
    <parent link="l_finger_1_link_0"/>
    <child link="l_finger_1_link_1"/>
    <axis xyz="0 0 1"/>
    <origin rpy="0 0 0" xyz="0.020 0 0"/>
    <limit effort="100" lower="0" upper="1.2217304764" velocity="100"/>
  </joint>
  <joint name="l_finger_1_joint_2" type="revolute">
    <parent link="l_finger_1_link_1"/>
    <child link="l_finger_1_link_2"/>
    <axis xyz="0 0 1"/>
    <origin rpy="0 0 -0.52" xyz="0.050 -.028 0"/>
    <limit effort="100" lower="0" upper="1.57079632679" velocity="100"/>
  </joint>
  <joint name="l_finger_1_joint_3" type="revolute">
    <parent link="l_finger_1_link_2"/>
    <child link="l_finger_1_link_3"/>
    <axis xyz="0 0 1"/>
    <origin rpy="0 0 0" xyz="0.039 0 0"/>
    <!-- upper limit -0.0523598775598 -->
    <limit effort="100" lower="-1.2217304764" upper="1.0" velocity="100"/>
  </joint>
  <link name="l_finger_2_link_0">
    <visual>
      <origin rpy="0 0 0" xyz="0.020 0 0"/>
      <geometry>
        <mesh filename="meshes/robotiq/visual/link_0.obj"/>
      </geometry>
      <material name="grey">
        <color rgba="0.3 0.3 0.3 1"/>
      </material>
    </visual>
    <inertial>
      <origin rpy="0 0 0" xyz="0 0 0"/>
      <mass value="0.02133"/>
      <inertia ixx="4.598e-06" ixy="2.211e-07" ixz="0.0" iyy="4.441e-06" iyz="0.0" izz="5.906e-06"/>
    </inertial>
  </link>
  <link name="l_finger_2_link_1">
    <visual>
      <origin rpy="0 0 -0.52" xyz="0.050 -.028 0"/>
      <geometry>
        <mesh filename="meshes/robotiq/visual/link_1.obj"/>
      </geometry>
      <material name="grey"/>
    </visual>
    <collision>
      <origin rpy="0 0 -0.61" xyz="0.028 -0.016 0.0"/>
      <geometry>
        <box size="0.048 0.018 0.0308"/>
      </geometry>
      <material name="red">
        <color rgba="1 0 0 1"/>
      </material>
      <surface>
        <friction>
          <ode>
            <mu>1.5</mu>
            <mu2>1.0</mu2>
          </ode>
        </friction>
      </surface>
    </collision>
    <inertial>
      <origin rpy="0 0 0" xyz="0 0 0"/>
      <mass value="0.10489"/>
      <inertia ixx="1.655e-05" ixy="-5.844e-07" ixz="0.0" iyy="7.334e-05" iyz="0.0" izz="8.054e-05"/>
    </inertial>
  </link>
  <link name="l_finger_2_link_2">
    <!--
				NOTE: This link has an offset in the z-direction based on the models that were
				used to generate grap-it poses.  With the offset below the model appears visually
				correct, but it is suspect.
				-->
    <visual>
      <origin rpy="0 0 0" xyz="0.039 0 0.0075"/>
      <geometry>
        <mesh filename="meshes/robotiq/visual/link_2.obj"/>
      </geometry>
      <material name="grey"/>
    </visual>
    <collision>
      <origin rpy="0 0 0.0" xyz="0.023 0.002 0.0"/>
      <geometry>
        <box size="0.0285 0.01 0.0308"/>
      </geometry>
      <material name="red">
        <color rgba="1 0 0 1"/>
      </material>
      <surface>
        <friction>
          <ode>
            <mu>1.5</mu>
            <mu2>1.0</mu2>
          </ode>
        </friction>
      </surface>
    </collision>
    <inertial>
      <origin rpy="0 0 0" xyz="0 0 0"/>
      <mass value="0.0601"/>
      <inertia ixx="7.304e-06" ixy="-2.645e-06" ixz="3.537e-07" iyy="1.918e-05" iyz="6.920e-07" izz="2.214e-05"/>
    </inertial>
  </link>
  <link name="l_finger_2_link_3">
    <visual>
      <origin rpy="0 0 0.52" xyz="0 0 0"/>
      <geometry>
        <mesh filename="meshes/robotiq/visual/link_3.obj"/>
      </geometry>
      <material name="grey"/>
    </visual>
    <collision>
      <origin rpy="0 0 0.58" xyz="0.015 0.0135 0.0"/>
      <geometry>
        <box size="0.03 0.007 0.0308"/>
      </geometry>
      <material name="red">
        <color rgba="1 0 0 1"/>
      </material>
      <surface>
        <friction>
          <ode>
            <mu>1.5</mu>
            <mu2>1.0</mu2>
          </ode>
        </friction>
      </surface>
    </collision>
    <inertial>
      <origin rpy="0 0 0" xyz="0 0 0"/>
      <mass value="0.024"/>
      <inertia ixx="2.021e-06" ixy="-7.733e-07" ixz="-1.031e-08" iyy="4.908e-06" iyz="0.0" izz="4.578e-06"/>
    </inertial>
  </link>
  <joint name="l_finger_2_joint_1" type="revolute">
    <parent link="l_finger_2_link_0"/>
    <child link="l_finger_2_link_1"/>
    <axis xyz="0 0 1"/>
    <origin rpy="0 0 0" xyz="0.020 0 0"/>
    <limit effort="100" lower="0" upper="1.2217304764" velocity="100"/>
  </joint>
  <joint name="l_finger_2_joint_2" type="revolute">
    <parent link="l_finger_2_link_1"/>
    <child link="l_finger_2_link_2"/>
    <axis xyz="0 0 1"/>
    <origin rpy="0 0 -0.52" xyz="0.050 -.028 0"/>
    <limit effort="100" lower="0" upper="1.57079632679" velocity="100"/>
  </joint>
  <joint name="l_finger_2_joint_3" type="revolute">
    <parent link="l_finger_2_link_2"/>
    <child link="l_finger_2_link_3"/>
    <axis xyz="0 0 1"/>
    <origin rpy="0 0 0" xyz="0.039 0 0"/>
    <!-- upper limit -0.0523598775598 -->
    <limit effort="100" lower="-1.2217304764" upper="1.0" velocity="100"/>
  </joint>
  <link name="l_finger_middle_link_0">
    <visual>
      <origin rpy="0 0 0" xyz="0.020 0 0"/>
      <geometry>
        <mesh filename="meshes/robotiq/visual/link_0.obj"/>
      </geometry>
      <material name="grey">
        <color rgba="0.3 0.3 0.3 1"/>
      </material>
    </visual>
    <inertial>
      <origin rpy="0 0 0" xyz="0 0 0"/>
      <mass value="0.02133"/>
      <inertia ixx="4.598e-06" ixy="2.211e-07" ixz="0.0" iyy="4.441e-06" iyz="0.0" izz="5.906e-06"/>
    </inertial>
  </link>
  <link name="l_finger_middle_link_1">
    <visual>
      <origin rpy="0 0 -0.52" xyz="0.050 -.028 0"/>
      <geometry>
        <mesh filename="meshes/robotiq/visual/link_1.obj"/>
      </geometry>
      <material name="grey"/>
    </visual>
    <collision>
      <origin rpy="0 0 -0.61" xyz="0.028 -0.016 0.0"/>
      <geometry>
        <box size="0.048 0.018 0.0308"/>
      </geometry>
      <material name="red">
        <color rgba="1 0 0 1"/>
      </material>
      <surface>
        <friction>
          <ode>
            <mu>1.5</mu>
            <mu2>1.0</mu2>
          </ode>
        </friction>
      </surface>
    </collision>
    <inertial>
      <origin rpy="0 0 0" xyz="0 0 0"/>
      <mass value="0.10489"/>
      <inertia ixx="1.655e-05" ixy="-5.844e-07" ixz="0.0" iyy="7.334e-05" iyz="0.0" izz="8.054e-05"/>
    </inertial>
  </link>
  <link name="l_finger_middle_link_2">
    <!--
				NOTE: This link has an offset in the z-direction based on the models that were
				used to generate grap-it poses.  With the offset below the model appears visually
				correct, but it is suspect.
				-->
    <visual>
      <origin rpy="0 0 0" xyz="0.039 0 0.0075"/>
      <geometry>
        <mesh filename="meshes/robotiq/visual/link_2.obj"/>
      </geometry>
      <material name="grey"/>
    </visual>
    <collision>
      <origin rpy="0 0 0.0" xyz="0.023 0.002 0.0"/>
      <geometry>
        <box size="0.0285 0.01 0.0308"/>
      </geometry>
      <material name="red">
        <color rgba="1 0 0 1"/>
      </material>
      <surface>
        <friction>
          <ode>
            <mu>1.5</mu>
            <mu2>1.0</mu2>
          </ode>
        </friction>
      </surface>
    </collision>
    <inertial>
      <origin rpy="0 0 0" xyz="0 0 0"/>
      <mass value="0.0601"/>
      <inertia ixx="7.304e-06" ixy="-2.645e-06" ixz="3.537e-07" iyy="1.918e-05" iyz="6.920e-07" izz="2.214e-05"/>
    </inertial>
  </link>
  <link name="l_finger_middle_link_3">
    <visual>
      <origin rpy="0 0 0.52" xyz="0 0 0"/>
      <geometry>
        <mesh filename="meshes/robotiq/visual/link_3.obj"/>
      </geometry>
      <material name="grey"/>
    </visual>
    <collision>
      <origin rpy="0 0 0.58" xyz="0.015 0.0135 0.0"/>
      <geometry>
        <box size="0.03 0.007 0.0308"/>
      </geometry>
      <material name="red">
        <color rgba="1 0 0 1"/>
      </material>
      <surface>
        <friction>
          <ode>
            <mu>1.5</mu>
            <mu2>1.0</mu2>
          </ode>
        </friction>
      </surface>
    </collision>
    <inertial>
      <origin rpy="0 0 0" xyz="0 0 0"/>
      <mass value="0.024"/>
      <inertia ixx="2.021e-06" ixy="-7.733e-07" ixz="-1.031e-08" iyy="4.908e-06" iyz="0.0" izz="4.578e-06"/>
    </inertial>
  </link>
  <joint name="l_finger_middle_joint_1" type="revolute">
    <parent link="l_finger_middle_link_0"/>
    <child link="l_finger_middle_link_1"/>
    <axis xyz="0 0 1"/>
    <origin rpy="0 0 0" xyz="0.020 0 0"/>
    <limit effort="100" lower="0" upper="1.2217304764" velocity="100"/>
  </joint>
  <joint name="l_finger_middle_joint_2" type="revolute">
    <parent link="l_finger_middle_link_1"/>
    <child link="l_finger_middle_link_2"/>
    <axis xyz="0 0 1"/>
    <origin rpy="0 0 -0.52" xyz="0.050 -.028 0"/>
    <limit effort="100" lower="0" upper="1.57079632679" velocity="100"/>
  </joint>
  <joint name="l_finger_middle_joint_3" type="revolute">
    <parent link="l_finger_middle_link_2"/>
    <child link="l_finger_middle_link_3"/>
    <hardwareInterface>EffortJointInterface</hardwareInterface>
    <axis xyz="0 0 1"/>
    <origin rpy="0 0 0" xyz="0.039 0 0"/>
    <!-- upper limit -0.0523598775598 -->
    <limit effort="100" lower="-1.2217304764" upper="1.0" velocity="100"/>
  </joint>
  <link name="l_palm">
    <visual>
      <geometry>
        <mesh filename="meshes/robotiq/visual/palm.obj"/>
      </geometry>
      <material name="grey">
        <color rgba="0.3 0.3 0.3 1"/>
      </material>
    </visual>
    <collision>
      <origin rpy="0 0 0" xyz="0.0 -0.001 0.0"/>
      <geometry>
        <box size="0.0425 0.1048 0.1302"/>
      </geometry>
      <material name="red">
        <color rgba="1 0 0 1"/>
      </material>
      <surface>
        <friction>
          <ode>
            <mu>1.5</mu>
            <mu2>1.0</mu2>
          </ode>
        </friction>
      </surface>
    </collision>
    <inertial>
      <origin rpy="0 0 0" xyz="0 0 0"/>
      <mass value="1.72568"/>
      <inertia ixx="2.983e-03" ixy="1.075e-04" ixz="4.738e-08" iyy="3.607e-03" iyz="0.0" izz="2.840e-03"/>
    </inertial>
  </link>
  <joint name="l_palm_finger_1_joint" type="fixed">
    <parent link="l_palm"/>
    <child link="l_finger_1_link_0"/>
    <!-- <axis xyz="0 1 0"/> -->
    <origin rpy="0 3 -1.57" xyz="-0.0455 0.0214 0.036"/>
    <!-- <limit effort="100" lower="-0.16" upper="0.25" velocity="100"/> -->
  </joint>

  <joint name="l_palm_finger_2_joint" type="fixed">
    <parent link="l_palm"/>
    <child link="l_finger_2_link_0"/>
    <!-- <axis xyz="0 1 0"/> -->
    <origin rpy="0 3.28318 -1.57" xyz="-0.0455 0.0214 -0.036"/>
    <!-- <limit effort="100" lower="-0.25" upper="0.16" velocity="100"/> -->
  </joint>

  <joint name="l_palm_finger_middle_joint" type="fixed">
    <parent link="l_palm"/>
    <child link="l_finger_middle_link_0"/>
    <axis xyz="0 0 1"/>
    <origin rpy="0 0 1.57" xyz="0.0455 0.0214 0"/>
  </joint>
</robot>